Workbook

Sheet 共通部あり・なし
A1: 共通部の実費を入れた場合・入れない場合の損益比較
A2: 共通部の実費＝発展会計の共通部（主に租税公課、年943,852円・前年実績）。「なし」は店舗だけの損益、「あり」は現在の計画、「本部費込み」は共通部の実費の代わりに管理会計の本部費（月15.8万円）を負担した場合（参考）。金額はすべて税抜・円。
A3: ※租税公課の中身（消費税の納付かどうか）は未確認。確認結果で「入力」シートB11を直すと、この表も自動で変わる。
A5: 1. 年間の損益（全月で同じ達成度の場合）
A6: 項目 | B6: 100%達成 共通部なし | C6: 100%達成 共通部あり（計画） | D6: 100%達成 本部費込み（参考） | E6: 105%達成 共通部なし | F6: 105%達成 共通部あり（計画） | G6: 105%達成 本部費込み（参考） | H6: 計算
A7: 達成度 | B7: =1 -> 1 | C7: =1 -> 1 | D7: =1 -> 1 | E7: =入力!$B$16 -> 1.05 | F7: =入力!$B$16 -> 1.05 | G7: =入力!$B$16 -> 1.05
A8: 売上 | B8: =入力!$B$19*B7 -> 63000000 | C8: =入力!$B$19*C7 -> 63000000 | D8: =入力!$B$19*D7 -> 63000000 | E8: =入力!$B$19*E7 -> 66150000 | F8: =入力!$B$19*F7 -> 66150000 | G8: =入力!$B$19*G7 -> 66150000 | H8: 年間の目標売上×達成度
A9: 粗利 | B9: =入力!$B$5*B7 -> 21500000 | C9: =入力!$B$5*C7 -> 21500000 | D9: =入力!$B$5*D7 -> 21500000 | E9: =入力!$B$5*E7 -> 22575000 | F9: =入力!$B$5*F7 -> 22575000 | G9: =入力!$B$5*G7 -> 22575000 | H9: 年間の目標粗利×達成度
A10: 人件費 | B10: =入力!$B$7*12 -> 9600000 | C10: =入力!$B$7*12 -> 9600000 | D10: =入力!$B$7*12 -> 9600000 | E10: =入力!$B$7*12 -> 9600000 | F10: =入力!$B$7*12 -> 9600000 | G10: =入力!$B$7*12 -> 9600000 | H10: 月80万円×12
A11: 報奨金 | B11: =IF(B7>=入力!$B$16,入力!$B$15,IF(B7>=1,入力!$B$14,0))*12 -> 360000 | C11: =IF(C7>=入力!$B$16,入力!$B$15,IF(C7>=1,入力!$B$14,0))*12 -> 360000 | D11: =IF(D7>=入力!$B$16,入力!$B$15,IF(D7>=1,入力!$B$14,0))*12 -> 360000 | E11: =IF(E7>=入力!$B$16,入力!$B$15,IF(E7>=1,入力!$B$14,0))*12 -> 600000 | F11: =IF(F7>=入力!$B$16,入力!$B$15,IF(F7>=1,入力!$B$14,0))*12 -> 600000 | G11: =IF(G7>=入力!$B$16,入力!$B$15,IF(G7>=1,入力!$B$14,0))*12 -> 600000 | H11: 全月達成の場合
A12: テナント経費 | B12: =入力!$B$8*12+B8*入力!$B$9 -> 6877104 | C12: =入力!$B$8*12+C8*入力!$B$9 -> 6877104 | D12: =入力!$B$8*12+D8*入力!$B$9 -> 6877104 | E12: =入力!$B$8*12+E8*入力!$B$9 -> 7095084 | F12: =入力!$B$8*12+F8*入力!$B$9 -> 7095084 | G12: =入力!$B$8*12+G8*入力!$B$9 -> 7095084 | H12: 固定分×12＋売上×連動率
A13: その他の店舗経費 | B13: =入力!$B$10 -> 3493268 | C13: =入力!$B$10 -> 3493268 | D13: =入力!$B$10 -> 3493268 | E13: =入力!$B$10 -> 3493268 | F13: =入力!$B$10 -> 3493268 | G13: =入力!$B$10 -> 3493268
A14: 店舗の費用 計 | B14: =SUM(B10:B13) -> 20330372 | C14: =SUM(C10:C13) -> 20330372 | D14: =SUM(D10:D13) -> 20330372 | E14: =SUM(E10:E13) -> 20788352 | F14: =SUM(F10:F13) -> 20788352 | G14: =SUM(G10:G13) -> 20788352 | H14: 人件費〜その他の店舗経費
A15: 店舗の利益（共通部・本部費を引く前） | B15: =B9-B14 -> 1169628 | C15: =C9-C14 -> 1169628 | D15: =D9-D14 -> 1169628 | E15: =E9-E14 -> 1786648 | F15: =F9-F14 -> 1786648 | G15: =G9-G14 -> 1786648 | H15: 粗利−店舗の費用 計
A16: 共通部の実費 | B16: 0 | C16: =入力!$B$11 -> 943852 | D16: 0 | E16: 0 | F16: =入力!$B$11 -> 943852 | G16: 0 | H16: 「あり」だけ計上
A17: 本部費 | B17: 0 | C17: 0 | D17: =入力!$B$12*12 -> 1896000 | E17: 0 | F17: 0 | G17: =入力!$B$12*12 -> 1896000 | H17: 「本部費込み」だけ計上（月15.8万円×12）
A18: 営業利益 | B18: =B15-B16-B17 -> 1169628 | C18: =C15-C16-C17 -> 225776 | D18: =D15-D16-D17 -> -726372 | E18: =E15-E16-E17 -> 1786648 | F18: =F15-F16-F17 -> 842796 | G18: =G15-G16-G17 -> -109352 | H18: 店舗の利益−共通部−本部費
A19: 営業外費用 | B19: =入力!$B$13 -> 300000 | C19: =入力!$B$13 -> 300000 | D19: =入力!$B$13 -> 300000 | E19: =入力!$B$13 -> 300000 | F19: =入力!$B$13 -> 300000 | G19: =入力!$B$13 -> 300000
A20: 経常利益 | B20: =B18-B19 -> 869628 | C20: =C18-C19 -> -74224 | D20: =D18-D19 -> -1026372 | E20: =E18-E19 -> 1486648 | F20: =F18-F19 -> 542796 | G20: =G18-G19 -> -409352
A21: 損益分岐の売上（報奨金前） | B21: =(入力!$B$7*12+入力!$B$8*12+入力!$B$10+B16+B17)/入力!$B$21 -> 57377811 | C21: =(入力!$B$7*12+入力!$B$8*12+入力!$B$10+C16+C17)/入力!$B$21 -> 60846965 | D21: =(入力!$B$7*12+入力!$B$8*12+入力!$B$10+D16+D17)/入力!$B$21 -> 64346610 | E21: =(入力!$B$7*12+入力!$B$8*12+入力!$B$10+E16+E17)/入力!$B$21 -> 57377811 | F21: =(入力!$B$7*12+入力!$B$8*12+入力!$B$10+F16+F17)/入力!$B$21 -> 60846965 | G21: =(入力!$B$7*12+入力!$B$8*12+入力!$B$10+G16+G17)/入力!$B$21 -> 64346610 | H21: （店舗の固定費＋共通部または本部費）÷限界利益率
A22: 損益分岐の達成度 | B22: =B21/入力!$B$19 -> 0.91075891 | C22: =C21/入力!$B$19 -> 0.96582483 | D22: =D21/入力!$B$19 -> 1.0213748 | E22: =E21/入力!$B$19 -> 0.91075891 | F22: =F21/入力!$B$19 -> 0.96582483 | G22: =G21/入力!$B$19 -> 1.0213748 | H22: 損益分岐の売上÷年間の目標売上
A25: 2. 達成度別の営業利益（「達成度別」シートの営業利益を基準に、共通部・本部費だけ入れ替え）
A26: 達成度 | B26: 共通部なし | C26: 共通部あり（計画） | D26: 本部費込み（参考） | E26: 共通部の負担額
A27: =達成度別!A4 -> 0.9 | B27: =C27+入力!$B$11 -> -184412 | C27: =達成度別!E4 -> -1128264 | D27: =C27+入力!$B$11-入力!$B$12*12 -> -2080412 | E27: =B27-C27 -> 943852
A28: =達成度別!A5 -> 0.95 | B28: =C28+入力!$B$11 -> 672608 | C28: =達成度別!E5 -> -271244 | D28: =C28+入力!$B$11-入力!$B$12*12 -> -1223392 | E28: =B28-C28 -> 943852
A29: =達成度別!A6 -> 1 | B29: =C29+入力!$B$11 -> 1169628 | C29: =達成度別!E6 -> 225776 | D29: =C29+入力!$B$11-入力!$B$12*12 -> -726372 | E29: =B29-C29 -> 943852
A30: =達成度別!A7 -> 1.03 | B30: =C30+入力!$B$11 -> 1683840 | C30: =達成度別!E7 -> 739988 | D30: =C30+入力!$B$11-入力!$B$12*12 -> -212160 | E30: =B30-C30 -> 943852
A31: =達成度別!A8 -> 1.05 | B31: =C31+入力!$B$11 -> 1786648 | C31: =達成度別!E8 -> 842796 | D31: =C31+入力!$B$11-入力!$B$12*12 -> -109352 | E31: =B31-C31 -> 943852
A32: =達成度別!A9 -> 1.1 | B32: =C32+入力!$B$11 -> 2643668 | C32: =達成度別!E9 -> 1699816 | D32: =C32+入力!$B$11-入力!$B$12*12 -> 747668 | E32: =B32-C32 -> 943852
A35: 3. 月別の営業利益（スマレジ版の目標・全月100%達成。共通部の実費と本部費は12等分）
A36: 月 | B36: 粗利目標100% | C36: 共通部なし | D36: 共通部あり（計画） | E36: 本部費込み（参考）
A37: ='月別（スマレジ版）'!A6 -> 8月 | B37: ='月別（スマレジ版）'!F6 -> 1250000 | C37: =D37+入力!$B$11/12 -> -336937.67 | D37: ='月別（スマレジ版）'!H6 -> -415592 | E37: =D37+入力!$B$11/12-入力!$B$12 -> -494937.67
A38: ='月別（スマレジ版）'!A7 -> 9月 | B38: ='月別（スマレジ版）'!F7 -> 1600000 | C38: =D38+入力!$B$11/12 -> -56137.667 | D38: ='月別（スマレジ版）'!H7 -> -134792 | E38: =D38+入力!$B$11/12-入力!$B$12 -> -214137.67
A39: ='月別（スマレジ版）'!A8 -> 10月 | B39: ='月別（スマレジ版）'!F8 -> 2000000 | C39: =D39+入力!$B$11/12 -> 267742.33 | D39: ='月別（スマレジ版）'!H8 -> 189088 | E39: =D39+入力!$B$11/12-入力!$B$12 -> 109742.33
A40: ='月別（スマレジ版）'!A9 -> 11月 | B40: ='月別（スマレジ版）'!F9 -> 2000000 | C40: =D40+入力!$B$11/12 -> 267742.33 | D40: ='月別（スマレジ版）'!H9 -> 189088 | E40: =D40+入力!$B$11/12-入力!$B$12 -> 109742.33
A41: ='月別（スマレジ版）'!A10 -> 12月 | B41: ='月別（スマレジ版）'!F10 -> 2500000 | C41: =D41+入力!$B$11/12 -> 663942.33 | D41: ='月別（スマレジ版）'!H10 -> 585288 | E41: =D41+入力!$B$11/12-入力!$B$12 -> 505942.33
A42: ='月別（スマレジ版）'!A11 -> 1月 | B42: ='月別（スマレジ版）'!F11 -> 2100000 | C42: =D42+入力!$B$11/12 -> 333142.33 | D42: ='月別（スマレジ版）'!H11 -> 254488 | E42: =D42+入力!$B$11/12-入力!$B$12 -> 175142.33
A43: ='月別（スマレジ版）'!A12 -> 2月 | B43: ='月別（スマレジ版）'!F12 -> 1250000 | C43: =D43+入力!$B$11/12 -> -336937.67 | D43: ='月別（スマレジ版）'!H12 -> -415592 | E43: =D43+入力!$B$11/12-入力!$B$12 -> -494937.67
A44: ='月別（スマレジ版）'!A13 -> 3月 | B44: ='月別（スマレジ版）'!F13 -> 2000000 | C44: =D44+入力!$B$11/12 -> 267742.33 | D44: ='月別（スマレジ版）'!H13 -> 189088 | E44: =D44+入力!$B$11/12-入力!$B$12 -> 109742.33
A45: ='月別（スマレジ版）'!A14 -> 4月 | B45: ='月別（スマレジ版）'!F14 -> 1600000 | C45: =D45+入力!$B$11/12 -> -56137.667 | D45: ='月別（スマレジ版）'!H14 -> -134792 | E45: =D45+入力!$B$11/12-入力!$B$12 -> -214137.67
...

Sheet 目標設定
A1: Weekends 2027年度 月別目標（売上6,300万円・粗利2,150万円・税抜）
A2: 金額はすべて税抜。判定はスマレジの粗利（税抜）で毎月行う。
A3: 目標の配分 | B3: 1 | C3: 1＝スマレジ版（店長が登録した予算の月比率・おすすめ） 2＝構成比版（前年の売上構成比）
A5: 月 | B5: 日数 | C5: 粗利目標（100%） | D5: 粗利目標（105%） | E5: 売上目標 | F5: 1日あたり粗利目標 | G5: 1日あたり売上目標 | H5: 報奨金 第1段階（店舗計） | I5: 報奨金 第2段階（店舗計）
A6: 8月 | B6: 31 | C6: =CHOOSE($B$3,'月別（スマレジ版）'!F6,月別目標と営業利益!F6) -> 1250000 | D6: =CHOOSE($B$3,'月別（スマレジ版）'!G6,月別目標と営業利益!G6) -> 1300000 | E6: =CHOOSE($B$3,'月別（スマレジ版）'!D6,月別目標と営業利益!D6) -> 3700000 | F6: =ROUND(C6/B6,-3) -> 40000 | G6: =ROUND(E6/B6,-3) -> 119000 | H6: =入力!$B$14 -> 30000 | I6: =入力!$B$15 -> 50000
A7: 9月 | B7: 30 | C7: =CHOOSE($B$3,'月別（スマレジ版）'!F7,月別目標と営業利益!F7) -> 1600000 | D7: =CHOOSE($B$3,'月別（スマレジ版）'!G7,月別目標と営業利益!G7) -> 1700000 | E7: =CHOOSE($B$3,'月別（スマレジ版）'!D7,月別目標と営業利益!D7) -> 4700000 | F7: =ROUND(C7/B7,-3) -> 53000 | G7: =ROUND(E7/B7,-3) -> 157000 | H7: =入力!$B$14 -> 30000 | I7: =入力!$B$15 -> 50000
A8: 10月 | B8: 31 | C8: =CHOOSE($B$3,'月別（スマレジ版）'!F8,月別目標と営業利益!F8) -> 2000000 | D8: =CHOOSE($B$3,'月別（スマレジ版）'!G8,月別目標と営業利益!G8) -> 2100000 | E8: =CHOOSE($B$3,'月別（スマレジ版）'!D8,月別目標と営業利益!D8) -> 5800000 | F8: =ROUND(C8/B8,-3) -> 65000 | G8: =ROUND(E8/B8,-3) -> 187000 | H8: =入力!$B$14 -> 30000 | I8: =入力!$B$15 -> 50000
A9: 11月 | B9: 30 | C9: =CHOOSE($B$3,'月別（スマレジ版）'!F9,月別目標と営業利益!F9) -> 2000000 | D9: =CHOOSE($B$3,'月別（スマレジ版）'!G9,月別目標と営業利益!G9) -> 2100000 | E9: =CHOOSE($B$3,'月別（スマレジ版）'!D9,月別目標と営業利益!D9) -> 5800000 | F9: =ROUND(C9/B9,-3) -> 67000 | G9: =ROUND(E9/B9,-3) -> 193000 | H9: =入力!$B$14 -> 30000 | I9: =入力!$B$15 -> 50000
A10: 12月 | B10: 31 | C10: =CHOOSE($B$3,'月別（スマレジ版）'!F10,月別目標と営業利益!F10) -> 2500000 | D10: =CHOOSE($B$3,'月別（スマレジ版）'!G10,月別目標と営業利益!G10) -> 2650000 | E10: =CHOOSE($B$3,'月別（スマレジ版）'!D10,月別目標と営業利益!D10) -> 7300000 | F10: =ROUND(C10/B10,-3) -> 81000 | G10: =ROUND(E10/B10,-3) -> 235000 | H10: =入力!$B$14 -> 30000 | I10: =入力!$B$15 -> 50000
A11: 1月 | B11: 31 | C11: =CHOOSE($B$3,'月別（スマレジ版）'!F11,月別目標と営業利益!F11) -> 2100000 | D11: =CHOOSE($B$3,'月別（スマレジ版）'!G11,月別目標と営業利益!G11) -> 2200000 | E11: =CHOOSE($B$3,'月別（スマレジ版）'!D11,月別目標と営業利益!D11) -> 6300000 | F11: =ROUND(C11/B11,-3) -> 68000 | G11: =ROUND(E11/B11,-3) -> 203000 | H11: =入力!$B$14 -> 30000 | I11: =入力!$B$15 -> 50000
A12: 2月 | B12: 28 | C12: =CHOOSE($B$3,'月別（スマレジ版）'!F12,月別目標と営業利益!F12) -> 1250000 | D12: =CHOOSE($B$3,'月別（スマレジ版）'!G12,月別目標と営業利益!G12) -> 1300000 | E12: =CHOOSE($B$3,'月別（スマレジ版）'!D12,月別目標と営業利益!D12) -> 3700000 | F12: =ROUND(C12/B12,-3) -> 45000 | G12: =ROUND(E12/B12,-3) -> 132000 | H12: =入力!$B$14 -> 30000 | I12: =入力!$B$15 -> 50000
A13: 3月 | B13: 31 | C13: =CHOOSE($B$3,'月別（スマレジ版）'!F13,月別目標と営業利益!F13) -> 2000000 | D13: =CHOOSE($B$3,'月別（スマレジ版）'!G13,月別目標と営業利益!G13) -> 2100000 | E13: =CHOOSE($B$3,'月別（スマレジ版）'!D13,月別目標と営業利益!D13) -> 5800000 | F13: =ROUND(C13/B13,-3) -> 65000 | G13: =ROUND(E13/B13,-3) -> 187000 | H13: =入力!$B$14 -> 30000 | I13: =入力!$B$15 -> 50000
A14: 4月 | B14: 30 | C14: =CHOOSE($B$3,'月別（スマレジ版）'!F14,月別目標と営業利益!F14) -> 1600000 | D14: =CHOOSE($B$3,'月別（スマレジ版）'!G14,月別目標と営業利益!G14) -> 1700000 | E14: =CHOOSE($B$3,'月別（スマレジ版）'!D14,月別目標と営業利益!D14) -> 4700000 | F14: =ROUND(C14/B14,-3) -> 53000 | G14: =ROUND(E14/B14,-3) -> 157000 | H14: =入力!$B$14 -> 30000 | I14: =入力!$B$15 -> 50000
A15: 5月 | B15: 31 | C15: =CHOOSE($B$3,'月別（スマレジ版）'!F15,月別目標と営業利益!F15) -> 1600000 | D15: =CHOOSE($B$3,'月別（スマレジ版）'!G15,月別目標と営業利益!G15) -> 1700000 | E15: =CHOOSE($B$3,'月別（スマレジ版）'!D15,月別目標と営業利益!D15) -> 4700000 | F15: =ROUND(C15/B15,-3) -> 52000 | G15: =ROUND(E15/B15,-3) -> 152000 | H15: =入力!$B$14 -> 30000 | I15: =入力!$B$15 -> 50000
A16: 6月 | B16: 30 | C16: =CHOOSE($B$3,'月別（スマレジ版）'!F16,月別目標と営業利益!F16) -> 2000000 | D16: =CHOOSE($B$3,'月別（スマレジ版）'!G16,月別目標と営業利益!G16) -> 2100000 | E16: =CHOOSE($B$3,'月別（スマレジ版）'!D16,月別目標と営業利益!D16) -> 5800000 | F16: =ROUND(C16/B16,-3) -> 67000 | G16: =ROUND(E16/B16,-3) -> 193000 | H16: =入力!$B$14 -> 30000 | I16: =入力!$B$15 -> 50000
A17: 7月 | B17: 31 | C17: =CHOOSE($B$3,'月別（スマレジ版）'!F17,月別目標と営業利益!F17) -> 1600000 | D17: =CHOOSE($B$3,'月別（スマレジ版）'!G17,月別目標と営業利益!G17) -> 1700000 | E17: =CHOOSE($B$3,'月別（スマレジ版）'!D17,月別目標と営業利益!D17) -> 4700000 | F17: =ROUND(C17/B17,-3) -> 52000 | G17: =ROUND(E17/B17,-3) -> 152000 | H17: =入力!$B$14 -> 30000 | I17: =入力!$B$15 -> 50000
A18: 年計 | B18: =SUM(B6:B17) -> 365 | C18: =SUM(C6:C17) -> 21500000 | D18: =SUM(D6:D17) -> 22650000 | E18: =SUM(E6:E17) -> 63000000 | H18: =SUM(H6:H17) -> 360000 | I18: =SUM(I6:I17) -> 600000
A19: 年間目標との差 | C19: =C18-入力!B5 -> 0 | E19: =E18-入力!B19 -> 0
A21: 1人あたりの報奨金（月額）
A22: 区分 | B22: 人数 | C22: 第1段階（100%以上） | D22: 第2段階（105%以上）
A23: ='報奨金（例B）'!A5 -> 店長 | B23: ='報奨金（例B）'!B5 -> 1 | C23: ='報奨金（例B）'!D5 -> 12000 | D23: ='報奨金（例B）'!E5 -> 20000
A24: ='報奨金（例B）'!A6 -> 古参パート | B24: ='報奨金（例B）'!B6 -> 1 | C24: ='報奨金（例B）'!D6 -> 8000 | D24: ='報奨金（例B）'!E6 -> 14000
A25: ='報奨金（例B）'!A7 -> その他パート | B25: ='報奨金（例B）'!B7 -> 2 | C25: ='報奨金（例B）'!D7 -> 5000 | D25: ='報奨金（例B）'!E7 -> 8000
A27: ルール
A28: ・その月の粗利（スマレジ・税抜）が「粗利目標（100%）」以上で第1段階、「粗利目標（105%）」以上で第2段階。売上目標は判定に使わない（目安）。
A29: ・判定は粗利額だけ。値引きで売上を作っても報奨金は出ない。処分品は粗利の計算から除く。
A30: ・判定は毎月、支払いは夏冬の賞与にまとめる案（社会保険・扶養への影響は社労士に確認）。
A31: ・日数は暦日。定休日を除いた営業日数にしたい場合は青字の日数を書き換える。

Sheet 入力
A1: Weekends 2027年度 予算と報奨金案（売上6,300万円・粗利2,150万円） 入力値
A2: 青字・黄色＝入力値（変えると全シートが再計算）。金額はすべて税抜・円。
A4: 項目 | B4: 値 | C4: 出所・備考
A5: 年間の目標粗利 | B5: 21500000 | C5: 検討案
A6: 目標粗利率（粗利÷売上） | B6: =B5/B19 -> 0.34126984 | C6: 計算値：2,150万円÷6,300万円
A7: 人件費（月） | B7: 800000 | C7: 年960万円（給与・賞与・法定福利込み）。報奨金は別枠
A8: テナント経費の固定分（月） | B8: 209792 | C8: 売上歩合制。前年12か月の回帰の切片
A9: テナント経費の売上連動率 | B9: 0.0692 | C9: 同上の傾き（決定係数0.94）
A10: その他の店舗経費（年） | B10: 3493268 | C10: 管理諸費・減価償却・旅費など。前年実績（発展会計 営業部）
A11: 共通部の実費（年） | B11: 943852 | C11: 主に租税公課。前年実績
A12: 本部費（月） | B12: 158000 | C12: 管理会計の共通費（参考：営業利益には含めない）
A13: 営業外費用（年） | B13: 300000 | C13: 社長案
A14: 報奨金 第1段階（店舗計・月） | B14: ='報奨金（例B）'!D8 -> 30000 | C14: 粗利が月の目標の100%以上。1人あたりの額は「報奨金（例B）」シートで入力
A15: 報奨金 第2段階（店舗計・月） | B15: ='報奨金（例B）'!E8 -> 50000 | C15: 粗利が月の目標の105%以上。同上
A16: 第2段階のライン | B16: 1.05
A18: 計算値
A19: 年間の目標売上 | B19: 63000000 | C19: 検討案（税抜）
A20: 年間の固定費 | B20: =B7*12+B8*12+B10+B11 -> 16554624 | C20: 人件費＋テナント固定分＋その他の店舗経費＋共通部の実費
A21: 限界利益率 | B21: =B6-B9 -> 0.27206984 | C21: 粗利率−テナント連動率
A22: 損益分岐の売上（報奨金前） | B22: =B20/B21 -> 60846965

Sheet 年間損益
A1: 年間の損益計画（100%・105%達成）
A3: 項目 | B3: 100%達成 | C3: 105%達成 | D3: 内訳・計算
A4: 達成度 | B4: 1 | C4: =入力!B16 -> 1.05
A5: 売上 | B5: =入力!$B$19*B4 -> 63000000 | C5: =入力!$B$19*C4 -> 66150000 | D5: 年6,300万円×達成度
A6: 粗利 | B6: =入力!$B$5*B4 -> 21500000 | C6: =入力!$B$5*C4 -> 22575000
A7: 人件費 | B7: =入力!$B$7*12 -> 9600000 | C7: =入力!$B$7*12 -> 9600000 | D7: 月80万円
A8: 報奨金 | B8: =入力!$B$14*12 -> 360000 | C8: =入力!$B$15*12 -> 600000 | D8: 全月達成の場合
A9: テナント経費 | B9: =入力!$B$8*12+B5*入力!$B$9 -> 6877104 | C9: =入力!$B$8*12+C5*入力!$B$9 -> 7095084 | D9: 固定分＋売上×連動率
A10: その他の店舗経費 | B10: =入力!$B$10 -> 3493268 | C10: =入力!$B$10 -> 3493268
A11: 共通部の実費 | B11: =入力!$B$11 -> 943852 | C11: =入力!$B$11 -> 943852
A12: 販管費 計 | B12: =SUM(B7:B11) -> 21274224 | C12: =SUM(C7:C11) -> 21732204
A13: 営業利益 | B13: =B6-B12 -> 225776 | C13: =C6-C12 -> 842796
A14: 営業外費用 | B14: =入力!$B$13 -> 300000 | C14: =入力!$B$13 -> 300000
A15: 経常利益 | B15: =B13-B14 -> -74224 | C15: =C13-C14 -> 542796
A16: 参考：本部費込みの営業利益 | B16: =B13+B11-入力!$B$12*12 -> -726372 | C16: =C13+C11-入力!$B$12*12 -> -109352 | D16: 共通部の実費を本部費に置き換え

Sheet 達成度別
A1: 達成度で営業利益がどう動くか（粗利率は入力値で一定）
A3: 達成度 | B3: 売上 | C3: 粗利 | D3: 報奨金（年） | E3: 営業利益 | F3: 経常利益
A4: 0.9 | B4: =入力!$B$19*A4 -> 56700000 | C4: =入力!$B$5*A4 -> 19350000 | D4: =IF(A4>=入力!$B$16,入力!$B$15,IF(A4>=1,入力!$B$14,0))*12 -> 0 | E4: =C4-B4*入力!$B$9-入力!$B$20-D4 -> -1128264 | F4: =E4-入力!$B$13 -> -1428264
A5: 0.95 | B5: =入力!$B$19*A5 -> 59850000 | C5: =入力!$B$5*A5 -> 20425000 | D5: =IF(A5>=入力!$B$16,入力!$B$15,IF(A5>=1,入力!$B$14,0))*12 -> 0 | E5: =C5-B5*入力!$B$9-入力!$B$20-D5 -> -271244 | F5: =E5-入力!$B$13 -> -571244
A6: 1 | B6: =入力!$B$19*A6 -> 63000000 | C6: =入力!$B$5*A6 -> 21500000 | D6: =IF(A6>=入力!$B$16,入力!$B$15,IF(A6>=1,入力!$B$14,0))*12 -> 360000 | E6: =C6-B6*入力!$B$9-入力!$B$20-D6 -> 225776 | F6: =E6-入力!$B$13 -> -74224
A7: 1.03 | B7: =入力!$B$19*A7 -> 64890000 | C7: =入力!$B$5*A7 -> 22145000 | D7: =IF(A7>=入力!$B$16,入力!$B$15,IF(A7>=1,入力!$B$14,0))*12 -> 360000 | E7: =C7-B7*入力!$B$9-入力!$B$20-D7 -> 739988 | F7: =E7-入力!$B$13 -> 439988
A8: 1.05 | B8: =入力!$B$19*A8 -> 66150000 | C8: =入力!$B$5*A8 -> 22575000 | D8: =IF(A8>=入力!$B$16,入力!$B$15,IF(A8>=1,入力!$B$14,0))*12 -> 600000 | E8: =C8-B8*入力!$B$9-入力!$B$20-D8 -> 842796 | F8: =E8-入力!$B$13 -> 542796
A9: 1.1 | B9: =入力!$B$19*A9 -> 69300000 | C9: =入力!$B$5*A9 -> 23650000 | D9: =IF(A9>=入力!$B$16,入力!$B$15,IF(A9>=1,入力!$B$14,0))*12 -> 600000 | E9: =C9-B9*入力!$B$9-入力!$B$20-D9 -> 1699816 | F9: =E9-入力!$B$13 -> 1399816
A11: 予算を1%超えるごとの営業利益の増加 | E11: =入力!B19*0.01*入力!B21 -> 171404

Sheet 粗利率別
A1: 粗利率で営業利益がどう動くか（売上は予算どおり）
A3: 粗利率 | B3: 粗利 | C3: 報奨金（年） | D3: 営業利益 | E3: 経常利益
A4: 0.31 | B4: =入力!$B$19*A4 -> 19530000 | C4: =IF(B4>=入力!$B$5*入力!$B$16-1,入力!$B$15,IF(B4>=入力!$B$5-1,入力!$B$14,0))*12 -> 0 | D4: =B4-入力!$B$19*入力!$B$9-入力!$B$20-C4 -> -1384224 | E4: =D4-入力!$B$13 -> -1684224
A5: 0.32 | B5: =入力!$B$19*A5 -> 20160000 | C5: =IF(B5>=入力!$B$5*入力!$B$16-1,入力!$B$15,IF(B5>=入力!$B$5-1,入力!$B$14,0))*12 -> 0 | D5: =B5-入力!$B$19*入力!$B$9-入力!$B$20-C5 -> -754224 | E5: =D5-入力!$B$13 -> -1054224
A6: 0.33 | B6: =入力!$B$19*A6 -> 20790000 | C6: =IF(B6>=入力!$B$5*入力!$B$16-1,入力!$B$15,IF(B6>=入力!$B$5-1,入力!$B$14,0))*12 -> 0 | D6: =B6-入力!$B$19*入力!$B$9-入力!$B$20-C6 -> -124224 | E6: =D6-入力!$B$13 -> -424224
A7: =入力!B6 -> 0.34126984 | B7: =入力!$B$19*A7 -> 21500000 | C7: =IF(B7>=入力!$B$5*入力!$B$16-1,入力!$B$15,IF(B7>=入力!$B$5-1,入力!$B$14,0))*12 -> 360000 | D7: =B7-入力!$B$19*入力!$B$9-入力!$B$20-C7 -> 225776 | E7: =D7-入力!$B$13 -> -74224
A8: 0.35 | B8: =入力!$B$19*A8 -> 22050000 | C8: =IF(B8>=入力!$B$5*入力!$B$16-1,入力!$B$15,IF(B8>=入力!$B$5-1,入力!$B$14,0))*12 -> 360000 | D8: =B8-入力!$B$19*入力!$B$9-入力!$B$20-C8 -> 775776 | E8: =D8-入力!$B$13 -> 475776
A9: 0.36 | B9: =入力!$B$19*A9 -> 22680000 | C9: =IF(B9>=入力!$B$5*入力!$B$16-1,入力!$B$15,IF(B9>=入力!$B$5-1,入力!$B$14,0))*12 -> 600000 | D9: =B9-入力!$B$19*入力!$B$9-入力!$B$20-C9 -> 1165776 | E9: =D9-入力!$B$13 -> 865776
A11: 粗利率1ポイントあたりの営業利益の変化 | D11: =入力!B19*0.01 -> 630000

Sheet 月別目標と営業利益
A1: 月別の目標と営業利益 構成比版（全月で100%達成した場合）
A2: 月の目標は前年（2025/8〜2026/7）の売上構成比で配分。固定費は12等分。黄色の実績粗利（スマレジ・税抜）を入れると段階と報奨金が出る。
A3: 黄色の「売上目標」は10万円単位（年計6,300万円）、「粗利目標100%」は5万円単位（年計2,150万円）に丸めた目標。105%は5万円単位。
A5: 月 | B5: 前年売上（参考） | C5: 比率 | D5: 売上目標 | E5: 粗利目標（丸め前） | F5: 粗利目標100% | G5: 粗利目標105% | H5: 営業利益（100%時） | I5: 累計 | J5: 実績粗利 | K5: 段階 | L5: 報奨金
A6: 8月 | B6: 3040292 | C6: =B6/SUM($B$6:$B$17) -> 0.056658124 | D6: 3600000 | E6: =ROUND(入力!$B$5*C6,-3) -> 1218000 | F6: 1200000 | G6: =ROUND(F6*入力!$B$16/50000,0)*50000 -> 1250000 | H6: =F6-D6*入力!$B$9-入力!$B$20/12-入力!$B$14 -> -458672 | I6: =SUM($H$6:H6) -> -458672 | K6: =IF(J6="","",IF(J6>=G6,2,IF(J6>=F6,1,0))) | L6: =IF(OR(K6="",K6=0),0,IF(K6=2,入力!$B$15,入力!$B$14)) -> 0
A7: 9月 | B7: 3638478 | C7: =B7/SUM($B$6:$B$17) -> 0.067805769 | D7: 4300000 | E7: =ROUND(入力!$B$5*C7,-3) -> 1458000 | F7: 1450000 | G7: =ROUND(F7*入力!$B$16/50000,0)*50000 -> 1500000 | H7: =F7-D7*入力!$B$9-入力!$B$20/12-入力!$B$14 -> -257112 | I7: =SUM($H$6:H7) -> -715784 | K7: =IF(J7="","",IF(J7>=G7,2,IF(J7>=F7,1,0))) | L7: =IF(OR(K7="",K7=0),0,IF(K7=2,入力!$B$15,入力!$B$14)) -> 0
A8: 10月 | B8: 4934704 | C8: =B8/SUM($B$6:$B$17) -> 0.091961914 | D8: 5800000 | E8: =ROUND(入力!$B$5*C8,-3) -> 1977000 | F8: 2000000 | G8: =ROUND(F8*入力!$B$16/50000,0)*50000 -> 2100000 | H8: =F8-D8*入力!$B$9-入力!$B$20/12-入力!$B$14 -> 189088 | I8: =SUM($H$6:H8) -> -526696 | K8: =IF(J8="","",IF(J8>=G8,2,IF(J8>=F8,1,0))) | L8: =IF(OR(K8="",K8=0),0,IF(K8=2,入力!$B$15,入力!$B$14)) -> 0
A9: 11月 | B9: 5149749 | C9: =B9/SUM($B$6:$B$17) -> 0.095969439 | D9: 6000000 | E9: =ROUND(入力!$B$5*C9,-3) -> 2063000 | F9: 2050000 | G9: =ROUND(F9*入力!$B$16/50000,0)*50000 -> 2150000 | H9: =F9-D9*入力!$B$9-入力!$B$20/12-入力!$B$14 -> 225248 | I9: =SUM($H$6:H9) -> -301448 | K9: =IF(J9="","",IF(J9>=G9,2,IF(J9>=F9,1,0))) | L9: =IF(OR(K9="",K9=0),0,IF(K9=2,入力!$B$15,入力!$B$14)) -> 0
A10: 12月 | B10: 6820952 | C10: =B10/SUM($B$6:$B$17) -> 0.12711356 | D10: 8000000 | E10: =ROUND(入力!$B$5*C10,-3) -> 2733000 | F10: 2750000 | G10: =ROUND(F10*入力!$B$16/50000,0)*50000 -> 2900000 | H10: =F10-D10*入力!$B$9-入力!$B$20/12-入力!$B$14 -> 786848 | I10: =SUM($H$6:H10) -> 485400 | K10: =IF(J10="","",IF(J10>=G10,2,IF(J10>=F10,1,0))) | L10: =IF(OR(K10="",K10=0),0,IF(K10=2,入力!$B$15,入力!$B$14)) -> 0
A11: 1月 | B11: 4850701 | C11: =B11/SUM($B$6:$B$17) -> 0.090396455 | D11: 5700000 | E11: =ROUND(入力!$B$5*C11,-3) -> 1944000 | F11: 1950000 | G11: =ROUND(F11*入力!$B$16/50000,0)*50000 -> 2050000 | H11: =F11-D11*入力!$B$9-入力!$B$20/12-入力!$B$14 -> 146008 | I11: =SUM($H$6:H11) -> 631408 | K11: =IF(J11="","",IF(J11>=G11,2,IF(J11>=F11,1,0))) | L11: =IF(OR(K11="",K11=0),0,IF(K11=2,入力!$B$15,入力!$B$14)) -> 0
A12: 2月 | B12: 2795656 | C12: =B12/SUM($B$6:$B$17) -> 0.052099149 | D12: 3300000 | E12: =ROUND(入力!$B$5*C12,-3) -> 1120000 | F12: 1100000 | G12: =ROUND(F12*入力!$B$16/50000,0)*50000 -> 1150000 | H12: =F12-D12*入力!$B$9-入力!$B$20/12-入力!$B$14 -> -537912 | I12: =SUM($H$6:H12) -> 93496 | K12: =IF(J12="","",IF(J12>=G12,2,IF(J12>=F12,1,0))) | L12: =IF(OR(K12="",K12=0),0,IF(K12=2,入力!$B$15,入力!$B$14)) -> 0
A13: 3月 | B13: 4419804 | C13: =B13/SUM($B$6:$B$17) -> 0.082366366 | D13: 5200000 | E13: =ROUND(入力!$B$5*C13,-3) -> 1771000 | F13: 1750000 | G13: =ROUND(F13*入力!$B$16/50000,0)*50000 -> 1850000 | H13: =F13-D13*入力!$B$9-入力!$B$20/12-入力!$B$14 -> -19392 | I13: =SUM($H$6:H13) -> 74104 | K13: =IF(J13="","",IF(J13>=G13,2,IF(J13>=F13,1,0))) | L13: =IF(OR(K13="",K13=0),0,IF(K13=2,入力!$B$15,入力!$B$14)) -> 0
A14: 4月 | B14: 3581469 | C14: =B14/SUM($B$6:$B$17) -> 0.066743364 | D14: 4200000 | E14: =ROUND(入力!$B$5*C14,-3) -> 1435000 | F14: 1450000 | G14: =ROUND(F14*入力!$B$16/50000,0)*50000 -> 1500000 | H14: =F14-D14*入力!$B$9-入力!$B$20/12-入力!$B$14 -> -250192 | I14: =SUM($H$6:H14) -> -176088 | K14: =IF(J14="","",IF(J14>=G14,2,IF(J14>=F14,1,0))) | L14: =IF(OR(K14="",K14=0),0,IF(K14=2,入力!$B$15,入力!$B$14)) -> 0
A15: 5月 | B15: 4799124 | C15: =B15/SUM($B$6:$B$17) -> 0.089435279 | D15: 5600000 | E15: =ROUND(入力!$B$5*C15,-3) -> 1923000 | F15: 1950000 | G15: =ROUND(F15*入力!$B$16/50000,0)*50000 -> 2050000 | H15: =F15-D15*入力!$B$9-入力!$B$20/12-入力!$B$14 -> 152928 | I15: =SUM($H$6:H15) -> -23160 | K15: =IF(J15="","",IF(J15>=G15,2,IF(J15>=F15,1,0))) | L15: =IF(OR(K15="",K15=0),0,IF(K15=2,入力!$B$15,入力!$B$14)) -> 0
A16: 6月 | B16: 4888307 | C16: =B16/SUM($B$6:$B$17) -> 0.091097271 | D16: 5700000 | E16: =ROUND(入力!$B$5*C16,-3) -> 1959000 | F16: 1950000 | G16: =ROUND(F16*入力!$B$16/50000,0)*50000 -> 2050000 | H16: =F16-D16*入力!$B$9-入力!$B$20/12-入力!$B$14 -> 146008 | I16: =SUM($H$6:H16) -> 122848 | K16: =IF(J16="","",IF(J16>=G16,2,IF(J16>=F16,1,0))) | L16: =IF(OR(K16="",K16=0),0,IF(K16=2,入力!$B$15,入力!$B$14)) -> 0
A17: 7月 | B17: 4741065 | C17: =B17/SUM($B$6:$B$17) -> 0.088353306 | D17: 5600000 | E17: =ROUND(入力!$B$5*C17,-3) -> 1900000 | F17: 1900000 | G17: =ROUND(F17*入力!$B$16/50000,0)*50000 -> 2000000 | H17: =F17-D17*入力!$B$9-入力!$B$20/12-入力!$B$14 -> 102928 | I17: =SUM($H$6:H17) -> 225776 | K17: =IF(J17="","",IF(J17>=G17,2,IF(J17>=F17,1,0))) | L17: =IF(OR(K17="",K17=0),0,IF(K17=2,入力!$B$15,入力!$B$14)) -> 0
A18: 年計 | B18: =SUM(B6:B17) -> 53660301 | D18: =SUM(D6:D17) -> 63000000 | E18: =SUM(E6:E17) -> 21501000 | F18: =SUM(F6:F17) -> 21500000 | G18: =SUM(G6:G17) -> 22550000 | H18: =SUM(H6:H17) -> 225776 | J18: =SUM(J6:J17) -> 0 | L18: =SUM(L6:L17) -> 0
A19: 年間目標との差 | D19: =D18-入力!B19 -> 0 | F19: =F18-入力!B5 -> 0
A20: （丸めた目標を直したら、D19とF19が0円になるように調整してください）

Sheet 月別（スマレジ版）
A1: 月別の目標と営業利益 スマレジ版（全月で100%達成した場合）
A2: 月の目標は、店長がスマレジに登録した店舗予算（年6,000万円・税抜）の月比率で配分。同じ予算額の月は同じ目標にそろえた。
A3: 黄色の「売上目標」は10万円単位（年計6,300万円）、「粗利目標100%」は5万円単位（年計2,150万円）に丸めた目標。105%は5万円単位。
A5: 月 | B5: スマレジ予算（参考） | C5: 比率 | D5: 売上目標 | E5: 粗利目標（丸め前） | F5: 粗利目標100% | G5: 粗利目標105% | H5: 営業利益（100%時） | I5: 累計 | J5: 構成比版との差（粗利目標） | K5: 実績粗利 | L5: 段階 | M5: 報奨金
A6: 8月 | B6: 3500000 | C6: =B6/SUM($B$6:$B$17) -> 0.058333333 | D6: 3700000 | E6: =ROUND(入力!$B$5*C6,-3) -> 1254000 | F6: 1250000 | G6: =ROUND(F6*入力!$B$16/50000,0)*50000 -> 1300000 | H6: =F6-D6*入力!$B$9-入力!$B$20/12-入力!$B$14 -> -415592 | I6: =SUM($H$6:H6) -> -415592 | J6: =F6-月別目標と営業利益!F6 -> 50000 | L6: =IF(K6="","",IF(K6>=G6,2,IF(K6>=F6,1,0))) | M6: =IF(OR(L6="",L6=0),0,IF(L6=2,入力!$B$15,入力!$B$14)) -> 0
A7: 9月 | B7: 4500000 | C7: =B7/SUM($B$6:$B$17) -> 0.075 | D7: 4700000 | E7: =ROUND(入力!$B$5*C7,-3) -> 1613000 | F7: 1600000 | G7: =ROUND(F7*入力!$B$16/50000,0)*50000 -> 1700000 | H7: =F7-D7*入力!$B$9-入力!$B$20/12-入力!$B$14 -> -134792 | I7: =SUM($H$6:H7) -> -550384 | J7: =F7-月別目標と営業利益!F7 -> 150000 | L7: =IF(K7="","",IF(K7>=G7,2,IF(K7>=F7,1,0))) | M7: =IF(OR(L7="",L7=0),0,IF(L7=2,入力!$B$15,入力!$B$14)) -> 0
A8: 10月 | B8: 5500000 | C8: =B8/SUM($B$6:$B$17) -> 0.091666667 | D8: 5800000 | E8: =ROUND(入力!$B$5*C8,-3) -> 1971000 | F8: 2000000 | G8: =ROUND(F8*入力!$B$16/50000,0)*50000 -> 2100000 | H8: =F8-D8*入力!$B$9-入力!$B$20/12-入力!$B$14 -> 189088 | I8: =SUM($H$6:H8) -> -361296 | J8: =F8-月別目標と営業利益!F8 -> 0 | L8: =IF(K8="","",IF(K8>=G8,2,IF(K8>=F8,1,0))) | M8: =IF(OR(L8="",L8=0),0,IF(L8=2,入力!$B$15,入力!$B$14)) -> 0
A9: 11月 | B9: 5500000 | C9: =B9/SUM($B$6:$B$17) -> 0.091666667 | D9: 5800000 | E9: =ROUND(入力!$B$5*C9,-3) -> 1971000 | F9: 2000000 | G9: =ROUND(F9*入力!$B$16/50000,0)*50000 -> 2100000 | H9: =F9-D9*入力!$B$9-入力!$B$20/12-入力!$B$14 -> 189088 | I9: =SUM($H$6:H9) -> -172208 | J9: =F9-月別目標と営業利益!F9 -> -50000 | L9: =IF(K9="","",IF(K9>=G9,2,IF(K9>=F9,1,0))) | M9: =IF(OR(L9="",L9=0),0,IF(L9=2,入力!$B$15,入力!$B$14)) -> 0
A10: 12月 | B10: 7000000 | C10: =B10/SUM($B$6:$B$17) -> 0.11666667 | D10: 7300000 | E10: =ROUND(入力!$B$5*C10,-3) -> 2508000 | F10: 2500000 | G10: =ROUND(F10*入力!$B$16/50000,0)*50000 -> 2650000 | H10: =F10-D10*入力!$B$9-入力!$B$20/12-入力!$B$14 -> 585288 | I10: =SUM($H$6:H10) -> 413080 | J10: =F10-月別目標と営業利益!F10 -> -250000 | L10: =IF(K10="","",IF(K10>=G10,2,IF(K10>=F10,1,0))) | M10: =IF(OR(L10="",L10=0),0,IF(L10=2,入力!$B$15,入力!$B$14)) -> 0
A11: 1月 | B11: 6000000 | C11: =B11/SUM($B$6:$B$17) -> 0.1 | D11: 6300000 | E11: =ROUND(入力!$B$5*C11,-3) -> 2150000 | F11: 2100000 | G11: =ROUND(F11*入力!$B$16/50000,0)*50000 -> 2200000 | H11: =F11-D11*入力!$B$9-入力!$B$20/12-入力!$B$14 -> 254488 | I11: =SUM($H$6:H11) -> 667568 | J11: =F11-月別目標と営業利益!F11 -> 150000 | L11: =IF(K11="","",IF(K11>=G11,2,IF(K11>=F11,1,0))) | M11: =IF(OR(L11="",L11=0),0,IF(L11=2,入力!$B$15,入力!$B$14)) -> 0
A12: 2月 | B12: 3500000 | C12: =B12/SUM($B$6:$B$17) -> 0.058333333 | D12: 3700000 | E12: =ROUND(入力!$B$5*C12,-3) -> 1254000 | F12: 1250000 | G12: =ROUND(F12*入力!$B$16/50000,0)*50000 -> 1300000 | H12: =F12-D12*入力!$B$9-入力!$B$20/12-入力!$B$14 -> -415592 | I12: =SUM($H$6:H12) -> 251976 | J12: =F12-月別目標と営業利益!F12 -> 150000 | L12: =IF(K12="","",IF(K12>=G12,2,IF(K12>=F12,1,0))) | M12: =IF(OR(L12="",L12=0),0,IF(L12=2,入力!$B$15,入力!$B$14)) -> 0
A13: 3月 | B13: 5500000 | C13: =B13/SUM($B$6:$B$17) -> 0.091666667 | D13: 5800000 | E13: =ROUND(入力!$B$5*C13,-3) -> 1971000 | F13: 2000000 | G13: =ROUND(F13*入力!$B$16/50000,0)*50000 -> 2100000 | H13: =F13-D13*入力!$B$9-入力!$B$20/12-入力!$B$14 -> 189088 | I13: =SUM($H$6:H13) -> 441064 | J13: =F13-月別目標と営業利益!F13 -> 250000 | L13: =IF(K13="","",IF(K13>=G13,2,IF(K13>=F13,1,0))) | M13: =IF(OR(L13="",L13=0),0,IF(L13=2,入力!$B$15,入力!$B$14)) -> 0
A14: 4月 | B14: 4500000 | C14: =B14/SUM($B$6:$B$17) -> 0.075 | D14: 4700000 | E14: =ROUND(入力!$B$5*C14,-3) -> 1613000 | F14: 1600000 | G14: =ROUND(F14*入力!$B$16/50000,0)*50000 -> 1700000 | H14: =F14-D14*入力!$B$9-入力!$B$20/12-入力!$B$14 -> -134792 | I14: =SUM($H$6:H14) -> 306272 | J14: =F14-月別目標と営業利益!F14 -> 150000 | L14: =IF(K14="","",IF(K14>=G14,2,IF(K14>=F14,1,0))) | M14: =IF(OR(L14="",L14=0),0,IF(L14=2,入力!$B$15,入力!$B$14)) -> 0
A15: 5月 | B15: 4500000 | C15: =B15/SUM($B$6:$B$17) -> 0.075 | D15: 4700000 | E15: =ROUND(入力!$B$5*C15,-3) -> 1613000 | F15: 1600000 | G15: =ROUND(F15*入力!$B$16/50000,0)*50000 -> 1700000 | H15: =F15-D15*入力!$B$9-入力!$B$20/12-入力!$B$14 -> -134792 | I15: =SUM($H$6:H15) -> 171480 | J15: =F15-月別目標と営業利益!F15 -> -350000 | L15: =IF(K15="","",IF(K15>=G15,2,IF(K15>=F15,1,0))) | M15: =IF(OR(L15="",L15=0),0,IF(L15=2,入力!$B$15,入力!$B$14)) -> 0
A16: 6月 | B16: 5500000 | C16: =B16/SUM($B$6:$B$17) -> 0.091666667 | D16: 5800000 | E16: =ROUND(入力!$B$5*C16,-3) -> 1971000 | F16: 2000000 | G16: =ROUND(F16*入力!$B$16/50000,0)*50000 -> 2100000 | H16: =F16-D16*入力!$B$9-入力!$B$20/12-入力!$B$14 -> 189088 | I16: =SUM($H$6:H16) -> 360568 | J16: =F16-月別目標と営業利益!F16 -> 50000 | L16: =IF(K16="","",IF(K16>=G16,2,IF(K16>=F16,1,0))) | M16: =IF(OR(L16="",L16=0),0,IF(L16=2,入力!$B$15,入力!$B$14)) -> 0
A17: 7月 | B17: 4500000 | C17: =B17/SUM($B$6:$B$17) -> 0.075 | D17: 4700000 | E17: =ROUND(入力!$B$5*C17,-3) -> 1613000 | F17: 1600000 | G17: =ROUND(F17*入力!$B$16/50000,0)*50000 -> 1700000 | H17: =F17-D17*入力!$B$9-入力!$B$20/12-入力!$B$14 -> -134792 | I17: =SUM($H$6:H17) -> 225776 | J17: =F17-月別目標と営業利益!F17 -> -300000 | L17: =IF(K17="","",IF(K17>=G17,2,IF(K17>=F17,1,0))) | M17: =IF(OR(L17="",L17=0),0,IF(L17=2,入力!$B$15,入力!$B$14)) -> 0
A18: 年計 | B18: =SUM(B6:B17) -> 60000000 | D18: =SUM(D6:D17) -> 63000000 | E18: =SUM(E6:E17) -> 21502000 | F18: =SUM(F6:F17) -> 21500000 | G18: =SUM(G6:G17) -> 22650000 | H18: =SUM(H6:H17) -> 225776 | K18: =SUM(K6:K17) -> 0 | M18: =SUM(M6:M17) -> 0
A19: 年間目標との差 | D19: =D18-入力!B19 -> 0 | F19: =F18-入力!B5 -> 0
A20: （丸めた目標を直したら、D19とF19が0円になるように調整してください）

Sheet 報奨金（例B）
A1: 報奨金の設計（例B）
A2: 毎月、その月の粗利（スマレジ・税抜）が目標の100%以上で第1段階、105%以上で第2段階。黄色の1人あたり月額を直接入力（店舗計は自動で入力シートに反映）。
A4: 区分 | B4: 人数 | C4: 店舗計に占める割合 | D4: 第1段階 1人月額（100%以上） | E4: 第2段階 1人月額（105%以上）
A5: 店長 | B5: 1 | C5: =B5*D5/$D$8 -> 0.4 | D5: 12000 | E5: 20000
A6: 古参パート | B6: 1 | C6: =B6*D6/$D$8 -> 0.26666667 | D6: 8000 | E6: 14000
A7: その他パート | B7: 2 | C7: =B7*D7/$D$8 -> 0.33333333 | D7: 5000 | E7: 8000
A8: 店舗計（月） | B8: =SUM(B5:B7) -> 4 | D8: =SUMPRODUCT(B5:B7,D5:D7) -> 30000 | E8: =SUMPRODUCT(B5:B7,E5:E7) -> 50000
A9: 全月達成した場合（年） | D9: =D8*12 -> 360000 | E9: =E8*12 -> 600000
A10: （第1段階は社長案の店舗計3万円を店長1.2万・古参0.8万・パート各0.5万で配分。第2段階は同じ比率で5万円を配分）
A12: ・判定は粗利額だけ（値引きで売上を作っても出ない）。処分品は粗利の計算から除く。
A13: ・判定は毎月、支払いは夏冬の賞与にまとめる案（社会保険・扶養への影響は社労士に確認）。
